Workbook

Sheet CTRL Condition
B1: 5x [um/Pxl] | C1: 1.2107986
B3: Shell (S) metrics obtained by image analysis. All data are reported in pixel. Images were acquired by using 5x optic. | M3: Necrotic core metrics obtained by image analysis. All data are reported in pixel. Images were acquired by using 5x optic.
B5: Obj 1 - S | C5: [Pixel] | M5: Obj 1 - C
B6: t [h] | C6: Area | D6: Angle | E6: Axis (major) | F6: Axis (minor) | G6: Diameter (max) | H6: Diameter (min) | I6: Diameter (mean) | J6: Center-X (mass) | K6: Center-Y (mass) | M6: t [h] | N6: Area | O6: Angle | P6: Axis (major) | Q6: Axis (minor) | R6: Diameter (max) | S6: Diameter (min) | T6: Diameter (mean) | U6: Center-X (mass) | V6: Center-Y (mass)
B7: 0 | C7: 25785 | D7: 1.029098 | E7: 195.8702 | F7: 167.9211 | G7: 199.6722 | H7: 162.1172 | I7: 179.8106 | J7: 606.125 | K7: 524.8304 | M7: 0 | N7: 7529 | O7: 12.26113 | P7: 102.4659 | Q7: 93.84816 | R7: 103.465 | S7: 88.75246 | T7: 96.75277 | U7: 622.1921 | V7: 534.6331
B8: 12 | C8: 30053 | D8: 39.70149 | E8: 201.5093 | F8: 190.1139 | G8: 204.1299 | H8: 182.6499 | I8: 194.4745 | J8: 615.4463 | K8: 510.14 | M8: 12 | N8: 11740 | O8: 52.07898 | P8: 132.3478 | Q8: 113.842 | R8: 134.5288 | S8: 106.4706 | T8: 120.7384 | U8: 638.0528 | V8: 510.9306
B9: 24 | C9: 47097 | D9: 40.15839 | E9: 251.7613 | F9: 238.6466 | G9: 255.7381 | H9: 227.3785 | I9: 243.4996 | J9: 609.1265 | K9: 502.686 | M9: 24 | N9: 12599 | O9: 58.36171 | P9: 143.7013 | Q9: 112.5091 | R9: 145 | S9: 103.2473 | T9: 124.8216 | U9: 647.0173 | V9: 504.9525
B10: 36 | C10: 44587 | D10: 23.56577 | E10: 242.9568 | F10: 234.0676 | G10: 249.5055 | H10: 226.3184 | I10: 237.1875 | J10: 608.6965 | K10: 502.1749 | M10: 36 | N10: 11303 | O10: 128.7799 | P10: 124.9443 | Q10: 117.0154 | R10: 132.3783 | S10: 100.7025 | T10: 118.4823 | U10: 642.1384 | V10: 502.7559
B11: 48 | C11: 44511 | D11: 20.2101 | E11: 241.949 | F11: 234.5203 | G11: 250.2818 | H11: 226.3736 | I11: 236.8356 | J11: 611.0491 | K11: 505.6545 | M11: 48 | N11: 12456 | O11: 111.0739 | P11: 139.7553 | Q11: 115.2211 | R11: 148.125 | S11: 97.94386 | T11: 123.8274 | U11: 639.4628 | V11: 515.3036
B13: Obj 2 - S | M13: Obj 2 - C
B14: t [h] | C14: Area | D14: Angle | E14: Axis (major) | F14: Axis (minor) | G14: Diameter (max) | H14: Diameter (min) | I14: Diameter (mean) | J14: Center-X (mass) | K14: Center-Y (mass) | M14: t [h] | N14: Area | O14: Angle | P14: Axis (major) | Q14: Axis (minor) | R14: Diameter (max) | S14: Diameter (min) | T14: Diameter (mean) | U14: Center-X (mass) | V14: Center-Y (mass)
B15: 0 | C15: 16740 | D15: 83.32138 | E15: 169.0074 | F15: 127.3034 | G15: 179.0447 | H15: 119.5073 | I15: 143.8957 | J15: 622.8181 | K15: 532.0796 | M15: 0 | N15: 2941 | O15: 89.64213 | P15: 74.11264 | Q15: 51.70871 | R15: 75.42546 | S15: 42.37924 | T15: 59.22306 | U15: 607.8234 | V15: 534.6249
B16: 12 | C16: 20308 | D16: 87.23871 | E16: 181.1751 | F16: 143.3601 | G16: 181.1767 | H16: 137.0036 | I16: 158.922 | J16: 624.6678 | K16: 525.6749 | M16: 12 | N16: 5024 | O16: 87.31789 | P16: 97.57502 | Q16: 67.01514 | R16: 98.0051 | S16: 54.12024 | T16: 77.7945 | U16: 624.0989 | V16: 515.5736
B17: 24 | C17: 32896 | D17: 85.39737 | E17: 224.8772 | F17: 186.8901 | G17: 224.4037 | H17: 173.3494 | I17: 202.9105 | J17: 630.6049 | K17: 526.4832 | M17: 24 | N17: 6952 | O17: 79.32869 | P17: 110.5941 | Q17: 81.149 | R17: 110.4536 | S17: 71.5891 | T17: 92.06947 | U17: 623.4183 | V17: 535.0903
B18: 36 | C18: 30653 | D18: 88.40385 | E18: 219.0262 | F18: 178.9826 | G18: 221 | H18: 168.0744 | I18: 195.8334 | J18: 626.9907 | K18: 526.1693 | M18: 36 | N18: 6960 | O18: 90.93754 | P18: 105.0685 | Q18: 86.10464 | R18: 115.7325 | S18: 76.6942 | T18: 92.40636 | U18: 613.4111 | V18: 530.2001
B19: 48 | C19: 36936 | D19: 88.60336 | E19: 239.9115 | F19: 196.6481 | G19: 241.6278 | H19: 183.7879 | I19: 215.0543 | J19: 631.4055 | K19: 530.9725 | M19: 48 | N19: 10507 | O19: 85.61722 | P19: 127.7378 | Q19: 105.4688 | R19: 133.7348 | S19: 95.88013 | T19: 114.1145 | U19: 622.4531 | V19: 533.2307
B21: Obj 3 - S | M21: Obj 3 - C
B22: t [h] | C22: Area | D22: Angle | E22: Axis (major) | F22: Axis (minor) | G22: Diameter (max) | H22: Diameter (min) | I22: Diameter (mean) | J22: Center-X (mass) | K22: Center-Y (mass) | M22: t [h] | N22: Area | O22: Angle | P22: Axis (major) | Q22: Axis (minor) | R22: Diameter (max) | S22: Diameter (min) | T22: Diameter (mean) | U22: Center-X (mass) | V22: Center-Y (mass)
B23: 0 | C23: 33046 | D23: 80.82194 | E23: 214.1209 | F23: 196.7696 | G23: 219.6588 | H23: 189.3198 | I23: 203.8752 | J23: 620.0119 | K23: 572.6424 | M23: 0 | N23: 10933 | O23: 99.79592 | P23: 132.7527 | Q23: 105.1322 | R23: 134.2386 | S23: 102.0441 | T23: 116.4375 | U23: 624.018 | V23: 551.7036
B24: 12 | C24: 41672 | D24: 85.38141 | E24: 239.7202 | F24: 221.5842 | G24: 246.0772 | H24: 216.0579 | I24: 229.2722 | J24: 627.3962 | K24: 569.0768 | M24: 12 | N24: 13702 | O24: 64.86569 | P24: 147.6117 | Q24: 119.1967 | R24: 152.0855 | S24: 114.0395 | T24: 130.3722 | U24: 617.7689 | V24: 547.1306
B25: 24 | C25: 70236 | D25: 103.1568 | E25: 309.5328 | F25: 289.6225 | G25: 323.0139 | H25: 283.0865 | I25: 297.5695 | J25: 629.0297 | K25: 563.8595 | M25: 24 | N25: 19459 | O25: 92.4667 | P25: 169.7988 | Q25: 146.7655 | R25: 173.7383 | S25: 138.2353 | T25: 156.0903 | U25: 616.8812 | V25: 535.5291
B26: 36 | C26: 61780 | D26: 93.86146 | E26: 289.9427 | F26: 271.7295 | G26: 297.2709 | H26: 264.8773 | I26: 279.2596 | J26: 627.5295 | K26: 567.7821 | M26: 36 | N26: 19002 | O26: 96.73819 | P26: 166.538 | Q26: 145.6987 | R26: 168.003 | S26: 141.6757 | T26: 154.3307 | U26: 626.0107 | V26: 542.6338
B27: 48 | C27: 62424 | D27: 88.72133 | E27: 296.8352 | F27: 268.1486 | G27: 302.9142 | H27: 256.4625 | I27: 280.6642 | J27: 629.3485 | K27: 573.4486 | M27: 48 | N27: 15449 | O27: 137.8798 | P27: 150.1677 | Q27: 131.4698 | R27: 155.5956 | S27: 125.6702 | T27: 138.8569 | U27: 619.2162 | V27: 535.9481
B29: Obj 4 - S | M29: Obj 4 - C
B30: t [h] | C30: Area | D30: Angle | E30: Axis (major) | F30: Axis (minor) | G30: Diameter (max) | H30: Diameter (min) | I30: Diameter (mean) | J30: Center-X (mass) | K30: Center-Y (mass) | M30: t [h] | N30: Area | O30: Angle | P30: Axis (major) | Q30: Axis (minor) | R30: Diameter (max) | S30: Diameter (min) | T30: Diameter (mean) | U30: Center-X (mass) | V30: Center-Y (mass)
B31: 0 | C31: 24195 | D31: 77.00549 | E31: 195.3141 | F31: 161.0158 | G31: 223.9732 | H31: 149.5627 | I31: 173.4771 | J31: 661.5823 | K31: 566.3793 | M31: 0 | N31: 7916 | O31: 57.68828 | P31: 104.1581 | Q31: 97.19669 | R31: 107.4895 | S31: 85.86617 | T31: 99.24673 | U31: 663.3047 | V31: 566.6304
B32: 12 | C32: 38892 | D32: 96.61675 | E32: 231.3088 | F32: 216.5841 | G32: 250.06 | H32: 202.4846 | I32: 220.8973 | J32: 665.0229 | K32: 556.046 | M32: 12 | N32: 11484 | O32: 12.27717 | P32: 123.8728 | Q32: 118.5964 | R32: 127.9414 | S32: 107.28 | T32: 119.6692 | U32: 646.1299 | V32: 552.4354
B33: 24 | C33: 55345 | D33: 23.33454 | E33: 271.287 | F33: 260.4806 | G33: 279.589 | H33: 238.0525 | I33: 264.1708 | J33: 660.8389 | K33: 559.8998 | M33: 24 | N33: 12947 | O33: 106.1722 | P33: 135.3866 | Q33: 122.4965 | R33: 143.1363 | S33: 115.434 | T33: 127.139 | U33: 634.7261 | V33: 553.1913
B34: 36 | C34: 55803 | D34: 31.40959 | E34: 273.4048 | F34: 260.4366 | G34: 277.5968 | H34: 248.6524 | I34: 265.331 | J34: 661.0292 | K34: 561.0831 | M34: 36 | N34: 10968 | O34: 122.0126 | P34: 120.5705 | Q34: 116.4092 | R34: 126.8109 | S34: 106.8878 | T34: 116.9982 | U34: 640.4419 | V34: 565.1287
B35: 48 | C35: 53939 | D35: 17.45797 | E35: 266.0623 | F35: 258.6896 | G35: 275.4088 | H35: 243.0514 | I35: 260.6454 | J35: 660.6329 | K35: 565.9924 | M35: 48 | N35: 10913 | O35: 16.24243 | P35: 123.3165 | Q35: 113.5957 | R35: 127.8828 | S35: 103.6195 | T35: 116.5551 | U35: 649.9193 | V35: 558.2543
B37: Obj 5 - S | M37: Obj 5 - C
B38: t [h] | C38: Area | D38: Angle | E38: Axis (major) | F38: Axis (minor) | G38: Diameter (max) | H38: Diameter (min) | I38: Diameter (mean) | J38: Center-X (mass) | K38: Center-Y (mass) | M38: t [h] | N38: Area | O38: Angle | P38: Axis (major) | Q38: Axis (minor) | R38: Diameter (max) | S38: Diameter (min) | T38: Diameter (mean) | U38: Center-X (mass) | V38: Center-Y (mass)
B39: 0 | C39: 24881 | D39: 82.96665 | E39: 186.1781 | F39: 170.3181 | G39: 190.8009 | H39: 166.3731 | I39: 176.8661 | J39: 688.6409 | K39: 488.4382 | M39: 0 | N39: 6044 | O39: 59.63981 | P39: 92.14108 | Q39: 84.21376 | R39: 95.60335 | S39: 77.93587 | T39: 86.68526 | U39: 686.1249 | V39: 475.3094
B40: 12 | C40: 44426 | D40: 176.6848 | E40: 247.0689 | F40: 229.6231 | G40: 257.4102 | H40: 220.4926 | I40: 236.7908 | J40: 693.5169 | K40: 484.2892 | M40: 12 | N40: 9644 | O40: 179.0458 | P40: 116.5865 | Q40: 106.0462 | R40: 120.9297 | S40: 99.32271 | T40: 109.5543 | U40: 709.5001 | V40: 467.4304
B41: 24 | C41: 62516 | D41: 172.3416 | E41: 292.4232 | F41: 272.9903 | G41: 301.0067 | H41: 258.5208 | I41: 280.6753 | J41: 697.2657 | K41: 488.729 | M41: 24 | N41: 17070 | O41: 124.2539 | P41: 153.7107 | Q41: 141.8646 | R41: 159.0503 | S41: 136.4185 | T41: 146.2822 | U41: 713.1696 | V41: 474.8893
B42: 36 | C42: 57683 | D42: 172.7933 | E42: 275.8039 | F42: 266.8501 | G42: 283.8045 | H42: 256.4703 | I42: 269.5853 | J42: 694.073 | K42: 486.57 | M42: 36 | N42: 15215 | O42: 58.55204 | P42: 152.5329 | Q42: 127.8285 | R42: 164.6572 | S42: 121.4949 | T42: 137.7312 | U42: 707.7814 | V42: 483.5951
B43: 48 | C43: 54466 | D43: 173.9971 | E43: 270.1801 | F43: 257.1403 | G43: 278.1259 | H43: 248.8453 | I43: 262.0717 | J43: 693.9377 | K43: 489.4105 | M43: 48 | N43: 17324 | O43: 108.8059 | P43: 157.5998 | Q43: 140.366 | R43: 161.9691 | S43: 135.2997 | T43: 147.3363 | U43: 708.9863 | V43: 487.506
B45: Obj 6 - S | M45: Obj 6 - C
B46: t [h] | C46: Area | D46: Angle | E46: Axis (major) | F46: Axis (minor) | G46: Diameter (max) | H46: Diameter (min) | I46: Diameter (mean) | J46: Center-X (mass) | K46: Center-Y (mass) | M46: t [h] | N46: Area | O46: Angle | P46: Axis (major) | Q46: Axis (minor) | R46: Diameter (max) | S46: Diameter (min) | T46: Diameter (mean) | U46: Center-X (mass) | V46: Center-Y (mass)
B47: 0 | C47: 17766 | D47: 162.9699 | E47: 163.3903 | F47: 140.4906 | G47: 165.1302 | H47: 133.6451 | I47: 148.5862 | J47: 631.3896 | K47: 541.6581 | M47: 0 | N47: 5734 | O47: 131.033 | P47: 96.25537 | Q47: 76.89795 | R47: 96.77293 | S47: 67.60178 | T47: 83.77796 | U47: 622.2018 | V47: 544.7916
...

Sheet Gradient condition
B1: 5x [um/Pxl] | C1: 1.2107986
B3: Shell (S) metrics obtained by image analysis. All data are reported in pixel. Images were acquired by using 5x optic. | M3: Necrotic core metrics obtained by image analysis. All data are reported in pixel. Images were acquired by using 5x optic.
B5: Data: | C5: 42576
B7: Obj 30 - S | C7: [Pixel] | M7: Obj 30 - C
B8: t [h] | C8: Area | D8: Angle | E8: Axis (major) | F8: Axis (minor) | G8: Diameter (max) | H8: Diameter (min) | I8: Diameter (mean) | J8: Center-X (mass) | K8: Center-Y (mass) | M8: t [h] | N8: Area | O8: Angle | P8: Axis (major) | Q8: Axis (minor) | R8: Diameter (max) | S8: Diameter (min) | T8: Diameter (mean) | U8: Center-X (mass) | V8: Center-Y (mass)
B9: 0 | C9: 37511 | D9: 176.5544 | E9: 233.6419 | F9: 205.035 | G9: 247.4066 | H9: 197.6689 | I9: 217.1771 | J9: 646.5122 | K9: 528.4769 | M9: 0 | N9: 16065 | O9: 143.8325 | P9: 147.4286 | Q9: 139.1356 | R9: 152.345 | S9: 130.0846 | T9: 141.9422 | U9: 645.3644 | V9: 505.491
B10: 12 | C10: 58430 | D10: 154.8746 | E10: 279.2249 | F10: 267.1228 | G10: 285.9738 | H10: 258.1414 | I10: 271.3729 | J10: 642.9349 | K10: 517.5927 | M10: 12 | N10: 20849 | O10: 51.66118 | P10: 169.3645 | Q10: 157.0302 | R10: 174.0029 | S10: 152.4861 | T10: 161.7678 | U10: 638.8703 | V10: 503.3575
B11: 24 | M11: 24
B12: 36 | C12: 71270 | D12: 160.8574 | E12: 313.3993 | F12: 290.1083 | G12: 322.1211 | H12: 279.0161 | I12: 300.0248 | J12: 646.2698 | K12: 544.0782 | M12: 36 | N12: 22555 | O12: 8.51075 | P12: 177.3102 | Q12: 162.0793 | R12: 178.3396 | S12: 158.0032 | T12: 168.4477 | U12: 638.8237 | V12: 524.3561
B13: 48 | C13: 68927 | D13: 144.9096 | E13: 321.0783 | F13: 274.0536 | G13: 332.3387 | H13: 260.8237 | I13: 294.4264 | J13: 644.1899 | K13: 526.2108 | M13: 48 | N13: 22654 | O13: 166.9894 | P13: 177.5803 | Q13: 162.6755 | R13: 184.3909 | S13: 156.9745 | T13: 168.7973 | U13: 642.5075 | V13: 527.7059
B15: Obj 31 - S | M15: Obj 31 - C
B16: t [h] | C16: Area | D16: Angle | E16: Axis (major) | F16: Axis (minor) | G16: Diameter (max) | H16: Diameter (min) | I16: Diameter (mean) | J16: Center-X (mass) | K16: Center-Y (mass) | M16: t [h] | N16: Area | O16: Angle | P16: Axis (major) | Q16: Axis (minor) | R16: Diameter (max) | S16: Diameter (min) | T16: Diameter (mean) | U16: Center-X (mass) | V16: Center-Y (mass)
B17: 0 | C17: 34523 | D17: 146.7702 | E17: 217.0396 | F17: 203.0419 | G17: 222.009 | H17: 191.802 | I17: 208.6557 | J17: 602.7392 | K17: 520.4521 | M17: 0 | N17: 18626 | O17: 111.1206 | P17: 169.6968 | Q17: 140.3027 | R17: 174.7484 | S17: 132.7403 | T17: 152.4143 | U17: 606.3447 | V17: 514.2783
B18: 12 | C18: 69216 | D18: 119.9041 | E18: 302.6544 | F18: 291.716 | G18: 310.266 | H18: 280.7294 | I18: 295.537 | J18: 600.5871 | K18: 517.6548 | M18: 12 | N18: 24840 | O18: 113.8204 | P18: 191.6427 | Q18: 165.2793 | R18: 195.5019 | S18: 162.0031 | T18: 176.6981 | U18: 603.5486 | V18: 507.8505
B19: 24 | C19: 90415 | D19: 24.09518 | E19: 349.5551 | F19: 330.5224 | G19: 363.4199 | H19: 315.1016 | I19: 337.8826 | J19: 607.5222 | K19: 518.8684 | M19: 24 | N19: 36580 | O19: 112.7024 | P19: 224.2714 | Q19: 207.9407 | R19: 229.2684 | S19: 202.7659 | T19: 214.7712 | U19: 609.0213 | V19: 522.7613
B20: 36 | C20: 88199 | D20: 155.8017 | E20: 346.6577 | F20: 324.7051 | G20: 354.1892 | H20: 300.9867 | I20: 333.7869 | J20: 601.1343 | K20: 527.3576 | M20: 36 | N20: 32138 | O20: 133.3081 | P20: 212.4171 | Q20: 193.1753 | R20: 217.9954 | S20: 183.807 | T20: 201.0009 | U20: 604.5259 | V20: 529.9354
B21: 48 | C21: 95852 | D21: 119.0952 | E21: 365.5811 | F21: 334.4885 | G21: 369.4388 | H21: 321.6598 | I21: 347.8985 | J21: 613.252 | K21: 508.2389 | M21: 48 | N21: 29749 | O21: 156.9347 | P21: 200.068 | Q21: 189.9071 | R21: 206.3201 | S21: 178.6309 | T21: 193.4751 | U21: 605.2201 | V21: 524.5112
B23: Obj 32 - S | M23: Obj 32 - C
B24: t [h] | C24: Area | D24: Angle | E24: Axis (major) | F24: Axis (minor) | G24: Diameter (max) | H24: Diameter (min) | I24: Diameter (mean) | J24: Center-X (mass) | K24: Center-Y (mass) | M24: t [h] | N24: Area | O24: Angle | P24: Axis (major) | Q24: Axis (minor) | R24: Diameter (max) | S24: Diameter (min) | T24: Diameter (mean) | U24: Center-X (mass) | V24: Center-Y (mass)
B25: 0 | C25: 37986 | D25: 62.02048 | E25: 230.7772 | F25: 211.1506 | G25: 238.5372 | H25: 205.3022 | I25: 218.191 | J25: 625.1964 | K25: 431.3981 | M25: 0 | N25: 15974 | O25: 39.50094 | P25: 152.2993 | Q25: 134.8664 | R25: 161.1986 | S25: 121.5936 | T25: 141.1694 | U25: 621.9538 | V25: 446.1312
B26: 12 | C26: 65150 | D26: 63.08996 | E26: 306.9677 | F26: 271.3601 | G26: 327 | H26: 258.1472 | I26: 286.6808 | J26: 627.1324 | K26: 431.5861 | M26: 12 | N26: 26787 | O26: 31.35517 | P26: 187.0172 | Q26: 182.662 | R26: 191.4706 | S26: 174.9286 | T26: 183.5772 | U26: 624.2632 | V26: 432.8812
B27: 24 | C27: 79647 | D27: 130.709 | E27: 328.2043 | F27: 310.2866 | G27: 349.1848 | H27: 295.2982 | I27: 316.737 | J27: 631.4168 | K27: 444.9417 | M27: 24 | N27: 33677 | O27: 51.29513 | P27: 217.8855 | Q27: 197.28 | R27: 222.1824 | S27: 191.802 | T27: 205.8253 | U27: 629.1555 | V27: 439.8797
B28: 36 | C28: 81026 | D28: 82.40424 | E28: 336.5718 | F28: 307.4839 | G28: 345.627 | H28: 298.0419 | I28: 319.5358 | J28: 624.8235 | K28: 428.8828 | M28: 36 | N28: 28631 | O28: 36.9044 | P28: 200.9121 | Q28: 182.3533 | R28: 206.9324 | S28: 168.3716 | T28: 189.5968 | U28: 625.0961 | V28: 432.3572
B29: 48 | C29: 82761 | D29: 74.03414 | E29: 345.0471 | F29: 305.7724 | G29: 352.6386 | H29: 297.7549 | I29: 323.229 | J29: 632.4789 | K29: 420.7469 | M29: 48 | N29: 28281 | O29: 62.10908 | P29: 201.5037 | Q29: 180.3244 | R29: 208.2907 | S29: 167.2872 | T29: 188.1872 | U29: 629.9355 | V29: 434.9269
B31: Obj 33 - S | M31: Obj 33 - C
B32: t [h] | C32: Area | D32: Angle | E32: Axis (major) | F32: Axis (minor) | G32: Diameter (max) | H32: Diameter (min) | I32: Diameter (mean) | J32: Center-X (mass) | K32: Center-Y (mass) | M32: t [h] | N32: Area | O32: Angle | P32: Axis (major) | Q32: Axis (minor) | R32: Diameter (max) | S32: Diameter (min) | T32: Diameter (mean) | U32: Center-X (mass) | V32: Center-Y (mass)
B33: 0 | C33: 35411 | D33: 136.4643 | E33: 230.2908 | F33: 196.0169 | G33: 238.296 | H33: 192.2134 | I33: 210.9526 | J33: 695.2615 | K33: 533.7311 | M33: 0 | N33: 20172 | O33: 139.5535 | P33: 170.3251 | Q33: 151.1599 | R33: 178.6309 | S33: 144.9414 | T33: 158.9529 | U33: 698.835 | V33: 528.4868
B34: 12 | C34: 61785 | D34: 160.9605 | E34: 296.0886 | F34: 266.4469 | G34: 306.3152 | H34: 247.8911 | I34: 278.7144 | J34: 699.6968 | K34: 529.8982 | M34: 12 | N34: 20701 | O34: 136.8236 | P34: 176.4875 | Q34: 149.717 | R34: 180.5602 | S34: 144.2775 | T34: 161.0578 | U34: 697.7876 | V34: 518.1377
B35: 24 | C35: 89667 | D35: 67.58777 | E35: 351.1754 | F35: 330.6734 | G35: 365.4532 | H35: 308.185 | I35: 334.9403 | J35: 676.2682 | K35: 540.7363 | M35: 24 | N35: 25883 | O35: 107.5015 | P35: 204.0924 | Q35: 161.9388 | R35: 206.526 | S35: 160.3278 | T35: 179.8156 | U35: 697.8375 | V35: 532.598
B36: 36 | C36: 88710 | D36: 133.4405 | E36: 358.7286 | F36: 316.1205 | G36: 374.9947 | H36: 299.5463 | I36: 334.5778 | J36: 687.9993 | K36: 539.9946 | M36: 36 | N36: 32834 | O36: 142.3362 | P36: 221.2863 | Q36: 189.444 | R36: 224.5373 | S36: 174.5222 | T36: 203.0202 | U36: 698.382 | V36: 535.5476
B37: 48 | C37: 88079 | D37: 146.5055 | E37: 362.3987 | F37: 310.2266 | G37: 373.4622 | H37: 302.8036 | I37: 332.9425 | J37: 695.7984 | K37: 521.9442 | M37: 48 | N37: 27372 | O37: 136.3457 | P37: 210.1258 | Q37: 166.4544 | R37: 209.9548 | S37: 159.7655 | T37: 184.8745 | U37: 709.3257 | V37: 532.5388
B39: Obj 34 - S | M39: Obj 34 - C
B40: t [h] | C40: Area | D40: Angle | E40: Axis (major) | F40: Axis (minor) | G40: Diameter (max) | H40: Diameter (min) | I40: Diameter (mean) | J40: Center-X (mass) | K40: Center-Y (mass) | M40: t [h] | N40: Area | O40: Angle | P40: Axis (major) | Q40: Axis (minor) | R40: Diameter (max) | S40: Diameter (min) | T40: Diameter (mean) | U40: Center-X (mass) | V40: Center-Y (mass)
B41: 0 | C41: 20771 | D41: 66.85121 | E41: 171.1037 | F41: 155.0302 | G41: 175.4109 | H41: 147.5568 | I41: 161.2974 | J41: 730.5649 | K41: 517.6856 | M41: 0 | N41: 4962 | O41: 114.3146 | P41: 85.2509 | Q41: 74.69022 | R41: 88.45903 | S41: 71.11962 | T41: 78.33419 | U41: 735.3807 | V41: 519.5376
B42: 12 | C42: 32188 | D42: 24.00152 | E42: 210.3295 | F42: 195.512 | G42: 217.681 | H42: 183.7417 | I42: 201.1483 | J42: 713.5332 | K42: 507.9956 | M42: 12 | N42: 8002 | O42: 49.68296 | P42: 108.6295 | Q42: 94.4139 | R42: 107.5639 | S42: 83.63013 | T42: 99.66256 | U42: 707.8226 | V42: 522.6587
B43: 24 | C43: 36056 | D43: 65.10387 | E43: 222.8507 | F43: 206.5707 | G43: 231.2488 | H43: 197.5854 | I43: 212.9429 | J43: 710.2688 | K43: 527.6936 | M43: 24 | N43: 10975 | O43: 59.86682 | P43: 131.6706 | Q43: 106.753 | R43: 131.244 | S43: 91.70605 | T43: 116.6668 | U43: 707.2634 | V43: 531.0389
B44: 36 | C44: 30645 | D44: 45.54447 | E44: 204.8031 | F44: 191.1322 | G44: 213.0211 | H44: 181.4635 | I44: 196.4722 | J44: 711.7864 | K44: 526.8845 | M44: 36 | N44: 7885 | O44: 14.36602 | P44: 117.9913 | Q44: 86.29738 | R44: 121.5936 | S44: 78.49203 | T44: 98.29646 | U44: 695.0861 | V44: 530.5547
B45: 48 | C45: 29368 | D45: 71.88854 | E45: 202.9609 | F45: 184.5199 | G45: 204.0098 | H45: 174.0259 | I45: 192.061 | J45: 713.0645 | K45: 527.4296 | M45: 48 | N45: 9695 | O45: 52.02244 | P45: 128.7549 | Q45: 96.72961 | R45: 128.7051 | S45: 82.92768 | T45: 109.1215 | U45: 700.6786 | V45: 529.8793
B47: Data: | C47: 42633
B49: Obj 1 - S | M49: Obj 1 - C
...

Sheet Average
A1: 5x [um/Pxl] | B1: 1.2107986
A3: Shell area | G3: Core area
A4: t [h] | B4: Area, Pxl^2 | C4: Area, μ^2 | D4: A/A0 | E4: SEM | G4: t [h] | H4: Area, Pxl^2 | I4: Area, μ^2 | J4: A/A0 | K4: SEM
A5: 0 | B5: =AVERAGE('CTRL Condition'!C7,'CTRL Condition'!C15,'CTRL Condition'!C23,'CTRL Condition'!C31,'CTRL Condition'!C39,'CTRL Condition'!C47,'CTRL Condition'!C55,'CTRL Condition'!C63,'CTRL Condition'!C71,'CTRL Condition'!C79,'CTRL Condition'!C87,'CTRL Condition'!C95,'CTRL Condition'!C103,'CTRL Condition'!C111,'CTRL Condition'!C119,'CTRL Condition'!C127,'CTRL Condition'!C135,'CTRL Condition'!C143,'CTRL Condition'!C151,'CTRL Condition'!C159,'CTRL Condition'!C167,'CTRL Condition'!C177,'CTRL Condition'!C185,'CTRL Condition'!C193) -> 21688.75 | C5: =B5*$B$1^2 -> 31796.428 | D5: =C5/C$5 -> 1 | E5: =STDEV('CTRL Condition'!C7,'CTRL Condition'!C15,'CTRL Condition'!C23,'CTRL Condition'!C31,'CTRL Condition'!C39,'CTRL Condition'!C47,'CTRL Condition'!C55,'CTRL Condition'!C63,'CTRL Condition'!C71,'CTRL Condition'!C79,'CTRL Condition'!C87,'CTRL Condition'!C95,'CTRL Condition'!C103,'CTRL Condition'!C111,'CTRL Condition'!C119,'CTRL Condition'!C127,'CTRL Condition'!C135,'CTRL Condition'!C143,'CTRL Condition'!C151,'CTRL Condition'!C159,'CTRL Condition'!C167,'CTRL Condition'!C177,'CTRL Condition'!C185,'CTRL Condition'!C193)*B$1*B$1/SQRT(COUNT('CTRL Condition'!C7,'CTRL Condition'!C15,'CTRL Condition'!C23,'CTRL Condition'!C31,'CTRL Condition'!C39,'CTRL Condition'!C47,'CTRL Condition'!C55,'CTRL Condition'!C63,'CTRL Condition'!C71,'CTRL Condition'!C79,'CTRL Condition'!C87,'CTRL Condition'!C95,'CTRL Condition'!C103,'CTRL Condition'!C111,'CTRL Condition'!C119,'CTRL Condition'!C127,'CTRL Condition'!C135,'CTRL Condition'!C143,'CTRL Condition'!C151,'CTRL Condition'!C159,'CTRL Condition'!C167,'CTRL Condition'!C177,'CTRL Condition'!C185,'CTRL Condition'!C193)) -> 1496.2386 | G5: 0 | H5: =AVERAGE('CTRL Condition'!N7,'CTRL Condition'!N15,'CTRL Condition'!N23,'CTRL Condition'!N31,'CTRL Condition'!N39,'CTRL Condition'!N47,'CTRL Condition'!N55,'CTRL Condition'!N63,'CTRL Condition'!N71,'CTRL Condition'!N79,'CTRL Condition'!N87,'CTRL Condition'!N95,'CTRL Condition'!N103,'CTRL Condition'!N111,'CTRL Condition'!N119,'CTRL Condition'!N127,'CTRL Condition'!N135,'CTRL Condition'!N143,'CTRL Condition'!N151,'CTRL Condition'!N159,'CTRL Condition'!N167,'CTRL Condition'!N177,'CTRL Condition'!N185,'CTRL Condition'!N193) -> 7551.7917 | I5: =H5*$B$1^2 -> 11071.177 | J5: =I5/I$5 -> 1 | K5: =STDEV('CTRL Condition'!N7,'CTRL Condition'!N15,'CTRL Condition'!N23,'CTRL Condition'!N31,'CTRL Condition'!N39,'CTRL Condition'!N47,'CTRL Condition'!N55,'CTRL Condition'!N63,'CTRL Condition'!N71,'CTRL Condition'!N79,'CTRL Condition'!N87,'CTRL Condition'!N95,'CTRL Condition'!N103,'CTRL Condition'!N111,'CTRL Condition'!N119,'CTRL Condition'!N127,'CTRL Condition'!N135,'CTRL Condition'!N143,'CTRL Condition'!N151,'CTRL Condition'!N159,'CTRL Condition'!N167,'CTRL Condition'!N177,'CTRL Condition'!N185,'CTRL Condition'!N193)/SQRT(COUNT('CTRL Condition'!N7,'CTRL Condition'!N15,'CTRL Condition'!N23,'CTRL Condition'!N31,'CTRL Condition'!N39,'CTRL Condition'!N47,'CTRL Condition'!N55,'CTRL Condition'!N63,'CTRL Condition'!N71,'CTRL Condition'!N79,'CTRL Condition'!N87,'CTRL Condition'!N95,'CTRL Condition'!N103,'CTRL Condition'!N111,'CTRL Condition'!N119,'CTRL Condition'!N127,'CTRL Condition'!N135,'CTRL Condition'!N143,'CTRL Condition'!N151,'CTRL Condition'!N159,'CTRL Condition'!N167,'CTRL Condition'!N177,'CTRL Condition'!N185,'CTRL Condition'!N193))*B$1*B$1 -> 777.72338
A6: 12 | B6: =AVERAGE('CTRL Condition'!C8,'CTRL Condition'!C16,'CTRL Condition'!C24,'CTRL Condition'!C32,'CTRL Condition'!C40,'CTRL Condition'!C48,'CTRL Condition'!C56,'CTRL Condition'!C64,'CTRL Condition'!C72,'CTRL Condition'!C80,'CTRL Condition'!C88,'CTRL Condition'!C96,'CTRL Condition'!C104,'CTRL Condition'!C112,'CTRL Condition'!C120,'CTRL Condition'!C128,'CTRL Condition'!C136,'CTRL Condition'!C144,'CTRL Condition'!C152,'CTRL Condition'!C160,'CTRL Condition'!C168,'CTRL Condition'!C178,'CTRL Condition'!C186,'CTRL Condition'!C194) -> 33713 | C6: =B6*$B$1^2 -> 49424.377 | D6: =C6/C$5 -> 1.5544003 | E6: =STDEV('CTRL Condition'!C8,'CTRL Condition'!C16,'CTRL Condition'!C24,'CTRL Condition'!C32,'CTRL Condition'!C40,'CTRL Condition'!C48,'CTRL Condition'!C56,'CTRL Condition'!C64,'CTRL Condition'!C72,'CTRL Condition'!C80,'CTRL Condition'!C88,'CTRL Condition'!C96,'CTRL Condition'!C104,'CTRL Condition'!C112,'CTRL Condition'!C120,'CTRL Condition'!C128,'CTRL Condition'!C136,'CTRL Condition'!C144,'CTRL Condition'!C152,'CTRL Condition'!C160,'CTRL Condition'!C168,'CTRL Condition'!C178,'CTRL Condition'!C186,'CTRL Condition'!C194)*B$1*B$1/SQRT(COUNT('CTRL Condition'!C8,'CTRL Condition'!C16,'CTRL Condition'!C24,'CTRL Condition'!C32,'CTRL Condition'!C40,'CTRL Condition'!C48,'CTRL Condition'!C56,'CTRL Condition'!C64,'CTRL Condition'!C72,'CTRL Condition'!C80,'CTRL Condition'!C88,'CTRL Condition'!C96,'CTRL Condition'!C104,'CTRL Condition'!C112,'CTRL Condition'!C120,'CTRL Condition'!C128,'CTRL Condition'!C136,'CTRL Condition'!C144,'CTRL Condition'!C152,'CTRL Condition'!C160,'CTRL Condition'!C168,'CTRL Condition'!C178,'CTRL Condition'!C186,'CTRL Condition'!C194)) -> 2419.3918 | G6: 12 | H6: =AVERAGE('CTRL Condition'!N8,'CTRL Condition'!N16,'CTRL Condition'!N24,'CTRL Condition'!N32,'CTRL Condition'!N40,'CTRL Condition'!N48,'CTRL Condition'!N56,'CTRL Condition'!N64,'CTRL Condition'!N72,'CTRL Condition'!N80,'CTRL Condition'!N88,'CTRL Condition'!N96,'CTRL Condition'!N104,'CTRL Condition'!N112,'CTRL Condition'!N120,'CTRL Condition'!N128,'CTRL Condition'!N136,'CTRL Condition'!N144,'CTRL Condition'!N152,'CTRL Condition'!N160,'CTRL Condition'!N168,'CTRL Condition'!N178,'CTRL Condition'!N186,'CTRL Condition'!N194) -> 11091.208 | I6: =H6*$B$1^2 -> 16260.08 | J6: =I6/I$5 -> 1.4686857 | K6: =STDEV('CTRL Condition'!N8,'CTRL Condition'!N16,'CTRL Condition'!N24,'CTRL Condition'!N32,'CTRL Condition'!N40,'CTRL Condition'!N48,'CTRL Condition'!N56,'CTRL Condition'!N64,'CTRL Condition'!N72,'CTRL Condition'!N80,'CTRL Condition'!N88,'CTRL Condition'!N96,'CTRL Condition'!N104,'CTRL Condition'!N112,'CTRL Condition'!N120,'CTRL Condition'!N128,'CTRL Condition'!N136,'CTRL Condition'!N144,'CTRL Condition'!N152,'CTRL Condition'!N160,'CTRL Condition'!N168,'CTRL Condition'!N178,'CTRL Condition'!N186,'CTRL Condition'!N194)/SQRT(COUNT('CTRL Condition'!N8,'CTRL Condition'!N16,'CTRL Condition'!N24,'CTRL Condition'!N32,'CTRL Condition'!N40,'CTRL Condition'!N48,'CTRL Condition'!N56,'CTRL Condition'!N64,'CTRL Condition'!N72,'CTRL Condition'!N80,'CTRL Condition'!N88,'CTRL Condition'!N96,'CTRL Condition'!N104,'CTRL Condition'!N112,'CTRL Condition'!N120,'CTRL Condition'!N128,'CTRL Condition'!N136,'CTRL Condition'!N144,'CTRL Condition'!N152,'CTRL Condition'!N160,'CTRL Condition'!N168,'CTRL Condition'!N178,'CTRL Condition'!N186,'CTRL Condition'!N194))*B$1*B$1 -> 1078.7772
A7: 24 | B7: =AVERAGE('CTRL Condition'!C9,'CTRL Condition'!C17,'CTRL Condition'!C25,'CTRL Condition'!C33,'CTRL Condition'!C41,'CTRL Condition'!C49,'CTRL Condition'!C57,'CTRL Condition'!C65,'CTRL Condition'!C73,'CTRL Condition'!C81,'CTRL Condition'!C89,'CTRL Condition'!C97,'CTRL Condition'!C105,'CTRL Condition'!C113,'CTRL Condition'!C121,'CTRL Condition'!C129,'CTRL Condition'!C137,'CTRL Condition'!C145,'CTRL Condition'!C153,'CTRL Condition'!C161,'CTRL Condition'!C169,'CTRL Condition'!C179,'CTRL Condition'!C187,'CTRL Condition'!C195) -> 52215.458 | C7: =B7*$B$1^2 -> 76549.595 | D7: =C7/C$5 -> 2.4074904 | E7: =STDEV('CTRL Condition'!C9,'CTRL Condition'!C17,'CTRL Condition'!C25,'CTRL Condition'!C33,'CTRL Condition'!C41,'CTRL Condition'!C49,'CTRL Condition'!C57,'CTRL Condition'!C65,'CTRL Condition'!C73,'CTRL Condition'!C81,'CTRL Condition'!C89,'CTRL Condition'!C97,'CTRL Condition'!C105,'CTRL Condition'!C113,'CTRL Condition'!C121,'CTRL Condition'!C129,'CTRL Condition'!C137,'CTRL Condition'!C145,'CTRL Condition'!C153,'CTRL Condition'!C161,'CTRL Condition'!C169,'CTRL Condition'!C179,'CTRL Condition'!C187,'CTRL Condition'!C195)*B$1*B$1/SQRT(COUNT('CTRL Condition'!C9,'CTRL Condition'!C17,'CTRL Condition'!C25,'CTRL Condition'!C33,'CTRL Condition'!C41,'CTRL Condition'!C49,'CTRL Condition'!C57,'CTRL Condition'!C65,'CTRL Condition'!C73,'CTRL Condition'!C81,'CTRL Condition'!C89,'CTRL Condition'!C97,'CTRL Condition'!C105,'CTRL Condition'!C113,'CTRL Condition'!C121,'CTRL Condition'!C129,'CTRL Condition'!C137,'CTRL Condition'!C145,'CTRL Condition'!C153,'CTRL Condition'!C161,'CTRL Condition'!C169,'CTRL Condition'!C179,'CTRL Condition'!C187,'CTRL Condition'!C195)) -> 3898.5583 | G7: 24 | H7: =AVERAGE('CTRL Condition'!N9,'CTRL Condition'!N17,'CTRL Condition'!N25,'CTRL Condition'!N33,'CTRL Condition'!N41,'CTRL Condition'!N49,'CTRL Condition'!N57,'CTRL Condition'!N65,'CTRL Condition'!N73,'CTRL Condition'!N81,'CTRL Condition'!N89,'CTRL Condition'!N97,'CTRL Condition'!N105,'CTRL Condition'!N113,'CTRL Condition'!N121,'CTRL Condition'!N129,'CTRL Condition'!N137,'CTRL Condition'!N145,'CTRL Condition'!N153,'CTRL Condition'!N161,'CTRL Condition'!N169,'CTRL Condition'!N179,'CTRL Condition'!N187,'CTRL Condition'!N195) -> 15342.375 | I7: =H7*$B$1^2 -> 22492.431 | J7: =I7/I$5 -> 2.0316205 | K7: =STDEV('CTRL Condition'!N9,'CTRL Condition'!N17,'CTRL Condition'!N25,'CTRL Condition'!N33,'CTRL Condition'!N41,'CTRL Condition'!N49,'CTRL Condition'!N57,'CTRL Condition'!N65,'CTRL Condition'!N73,'CTRL Condition'!N81,'CTRL Condition'!N89,'CTRL Condition'!N97,'CTRL Condition'!N105,'CTRL Condition'!N113,'CTRL Condition'!N121,'CTRL Condition'!N129,'CTRL Condition'!N137,'CTRL Condition'!N145,'CTRL Condition'!N153,'CTRL Condition'!N161,'CTRL Condition'!N169,'CTRL Condition'!N179,'CTRL Condition'!N187,'CTRL Condition'!N195)/SQRT(COUNT('CTRL Condition'!N9,'CTRL Condition'!N17,'CTRL Condition'!N25,'CTRL Condition'!N33,'CTRL Condition'!N41,'CTRL Condition'!N49,'CTRL Condition'!N57,'CTRL Condition'!N65,'CTRL Condition'!N73,'CTRL Condition'!N81,'CTRL Condition'!N89,'CTRL Condition'!N97,'CTRL Condition'!N105,'CTRL Condition'!N113,'CTRL Condition'!N121,'CTRL Condition'!N129,'CTRL Condition'!N137,'CTRL Condition'!N145,'CTRL Condition'!N153,'CTRL Condition'!N161,'CTRL Condition'!N169,'CTRL Condition'!N179,'CTRL Condition'!N187,'CTRL Condition'!N195))*B$1*B$1 -> 1333.4893
A8: 36 | B8: =AVERAGE('CTRL Condition'!C10,'CTRL Condition'!C18,'CTRL Condition'!C26,'CTRL Condition'!C34,'CTRL Condition'!C42,'CTRL Condition'!C50,'CTRL Condition'!C58,'CTRL Condition'!C66,'CTRL Condition'!C74,'CTRL Condition'!C82,'CTRL Condition'!C90,'CTRL Condition'!C98,'CTRL Condition'!C106,'CTRL Condition'!C114,'CTRL Condition'!C122,'CTRL Condition'!C130,'CTRL Condition'!C138,'CTRL Condition'!C146,'CTRL Condition'!C154,'CTRL Condition'!C162,'CTRL Condition'!C170,'CTRL Condition'!C180,'CTRL Condition'!C188,'CTRL Condition'!C196) -> 51604.958 | C8: =B8*$B$1^2 -> 75654.582 | D8: =C8/C$5 -> 2.3793422 | E8: =STDEV('CTRL Condition'!C10,'CTRL Condition'!C18,'CTRL Condition'!C26,'CTRL Condition'!C34,'CTRL Condition'!C42,'CTRL Condition'!C50,'CTRL Condition'!C58,'CTRL Condition'!C66,'CTRL Condition'!C74,'CTRL Condition'!C82,'CTRL Condition'!C90,'CTRL Condition'!C98,'CTRL Condition'!C106,'CTRL Condition'!C114,'CTRL Condition'!C122,'CTRL Condition'!C130,'CTRL Condition'!C138,'CTRL Condition'!C146,'CTRL Condition'!C154,'CTRL Condition'!C162,'CTRL Condition'!C170,'CTRL Condition'!C180,'CTRL Condition'!C188,'CTRL Condition'!C196)*B$1*B$1/SQRT(COUNT('CTRL Condition'!C10,'CTRL Condition'!C18,'CTRL Condition'!C26,'CTRL Condition'!C34,'CTRL Condition'!C42,'CTRL Condition'!C50,'CTRL Condition'!C58,'CTRL Condition'!C66,'CTRL Condition'!C74,'CTRL Condition'!C82,'CTRL Condition'!C90,'CTRL Condition'!C98,'CTRL Condition'!C106,'CTRL Condition'!C114,'CTRL Condition'!C122,'CTRL Condition'!C130,'CTRL Condition'!C138,'CTRL Condition'!C146,'CTRL Condition'!C154,'CTRL Condition'!C162,'CTRL Condition'!C170,'CTRL Condition'!C180,'CTRL Condition'!C188,'CTRL Condition'!C196)) -> 3875.2852 | G8: 36 | H8: =AVERAGE('CTRL Condition'!N10,'CTRL Condition'!N18,'CTRL Condition'!N26,'CTRL Condition'!N34,'CTRL Condition'!N42,'CTRL Condition'!N50,'CTRL Condition'!N58,'CTRL Condition'!N66,'CTRL Condition'!N74,'CTRL Condition'!N82,'CTRL Condition'!N90,'CTRL Condition'!N98,'CTRL Condition'!N106,'CTRL Condition'!N114,'CTRL Condition'!N122,'CTRL Condition'!N130,'CTRL Condition'!N138,'CTRL Condition'!N146,'CTRL Condition'!N154,'CTRL Condition'!N162,'CTRL Condition'!N170,'CTRL Condition'!N180,'CTRL Condition'!N188,'CTRL Condition'!N196) -> 15432.5 | I8: =H8*$B$1^2 -> 22624.557 | J8: =I8/I$5 -> 2.0435548 | K8: =STDEV('CTRL Condition'!N10,'CTRL Condition'!N18,'CTRL Condition'!N26,'CTRL Condition'!N34,'CTRL Condition'!N42,'CTRL Condition'!N50,'CTRL Condition'!N58,'CTRL Condition'!N66,'CTRL Condition'!N74,'CTRL Condition'!N82,'CTRL Condition'!N90,'CTRL Condition'!N98,'CTRL Condition'!N106,'CTRL Condition'!N114,'CTRL Condition'!N122,'CTRL Condition'!N130,'CTRL Condition'!N138,'CTRL Condition'!N146,'CTRL Condition'!N154,'CTRL Condition'!N162,'CTRL Condition'!N170,'CTRL Condition'!N180,'CTRL Condition'!N188,'CTRL Condition'!N196)/SQRT(COUNT('CTRL Condition'!N10,'CTRL Condition'!N18,'CTRL Condition'!N26,'CTRL Condition'!N34,'CTRL Condition'!N42,'CTRL Condition'!N50,'CTRL Condition'!N58,'CTRL Condition'!N66,'CTRL Condition'!N74,'CTRL Condition'!N82,'CTRL Condition'!N90,'CTRL Condition'!N98,'CTRL Condition'!N106,'CTRL Condition'!N114,'CTRL Condition'!N122,'CTRL Condition'!N130,'CTRL Condition'!N138,'CTRL Condition'!N146,'CTRL Condition'!N154,'CTRL Condition'!N162,'CTRL Condition'!N170,'CTRL Condition'!N180,'CTRL Condition'!N188,'CTRL Condition'!N196))*B$1*B$1 -> 1570.4603
A9: 48 | B9: =AVERAGE('CTRL Condition'!C11,'CTRL Condition'!C19,'CTRL Condition'!C27,'CTRL Condition'!C35,'CTRL Condition'!C43,'CTRL Condition'!C51,'CTRL Condition'!C59,'CTRL Condition'!C67,'CTRL Condition'!C75,'CTRL Condition'!C83,'CTRL Condition'!C91,'CTRL Condition'!C99,'CTRL Condition'!C107,'CTRL Condition'!C115,'CTRL Condition'!C123,'CTRL Condition'!C131,'CTRL Condition'!C139,'CTRL Condition'!C147,'CTRL Condition'!C155,'CTRL Condition'!C163,'CTRL Condition'!C171,'CTRL Condition'!C181,'CTRL Condition'!C189,'CTRL Condition'!C197) -> 51733.667 | C9: =B9*$B$1^2 -> 75843.273 | D9: =C9/C$5 -> 2.3852765 | E9: =STDEV('CTRL Condition'!C11,'CTRL Condition'!C19,'CTRL Condition'!C27,'CTRL Condition'!C35,'CTRL Condition'!C43,'CTRL Condition'!C51,'CTRL Condition'!C59,'CTRL Condition'!C67,'CTRL Condition'!C75,'CTRL Condition'!C83,'CTRL Condition'!C91,'CTRL Condition'!C99,'CTRL Condition'!C107,'CTRL Condition'!C115,'CTRL Condition'!C123,'CTRL Condition'!C131,'CTRL Condition'!C139,'CTRL Condition'!C147,'CTRL Condition'!C155,'CTRL Condition'!C163,'CTRL Condition'!C171,'CTRL Condition'!C181,'CTRL Condition'!C189,'CTRL Condition'!C197)*B$1*B$1/SQRT(COUNT('CTRL Condition'!C11,'CTRL Condition'!C19,'CTRL Condition'!C27,'CTRL Condition'!C35,'CTRL Condition'!C43,'CTRL Condition'!C51,'CTRL Condition'!C59,'CTRL Condition'!C67,'CTRL Condition'!C75,'CTRL Condition'!C83,'CTRL Condition'!C91,'CTRL Condition'!C99,'CTRL Condition'!C107,'CTRL Condition'!C115,'CTRL Condition'!C123,'CTRL Condition'!C131,'CTRL Condition'!C139,'CTRL Condition'!C147,'CTRL Condition'!C155,'CTRL Condition'!C163,'CTRL Condition'!C171,'CTRL Condition'!C181,'CTRL Condition'!C189,'CTRL Condition'!C197)) -> 3771.1641 | G9: 48 | H9: =AVERAGE('CTRL Condition'!N11,'CTRL Condition'!N19,'CTRL Condition'!N27,'CTRL Condition'!N35,'CTRL Condition'!N43,'CTRL Condition'!N51,'CTRL Condition'!N59,'CTRL Condition'!N67,'CTRL Condition'!N75,'CTRL Condition'!N83,'CTRL Condition'!N91,'CTRL Condition'!N99,'CTRL Condition'!N107,'CTRL Condition'!N115,'CTRL Condition'!N123,'CTRL Condition'!N131,'CTRL Condition'!N139,'CTRL Condition'!N147,'CTRL Condition'!N155,'CTRL Condition'!N163,'CTRL Condition'!N171,'CTRL Condition'!N181,'CTRL Condition'!N189,'CTRL Condition'!N197) -> 16277.75 | I9: =H9*$B$1^2 -> 23863.722 | J9: =I9/I$5 -> 2.1554819 | K9: =STDEV('CTRL Condition'!N11,'CTRL Condition'!N19,'CTRL Condition'!N27,'CTRL Condition'!N35,'CTRL Condition'!N43,'CTRL Condition'!N51,'CTRL Condition'!N59,'CTRL Condition'!N67,'CTRL Condition'!N75,'CTRL Condition'!N83,'CTRL Condition'!N91,'CTRL Condition'!N99,'CTRL Condition'!N107,'CTRL Condition'!N115,'CTRL Condition'!N123,'CTRL Condition'!N131,'CTRL Condition'!N139,'CTRL Condition'!N147,'CTRL Condition'!N155,'CTRL Condition'!N163,'CTRL Condition'!N171,'CTRL Condition'!N181,'CTRL Condition'!N189,'CTRL Condition'!N197)/SQRT(COUNT('CTRL Condition'!N11,'CTRL Condition'!N19,'CTRL Condition'!N27,'CTRL Condition'!N35,'CTRL Condition'!N43,'CTRL Condition'!N51,'CTRL Condition'!N59,'CTRL Condition'!N67,'CTRL Condition'!N75,'CTRL Condition'!N83,'CTRL Condition'!N91,'CTRL Condition'!N99,'CTRL Condition'!N107,'CTRL Condition'!N115,'CTRL Condition'!N123,'CTRL Condition'!N131,'CTRL Condition'!N139,'CTRL Condition'!N147,'CTRL Condition'!N155,'CTRL Condition'!N163,'CTRL Condition'!N171,'CTRL Condition'!N181,'CTRL Condition'!N189,'CTRL Condition'!N197))*B$1*B$1 -> 1502.0558
A11: Shell area | G11: Core area
A12: t [h] | B12: Area, Pxl^2 | C12: Area, μ^2 | D12: A/A0 | E12: SEM | G12: t [h] | H12: Area, Pxl^2 | I12: Area, μ^2 | J12: A/A0 | K12: SEM
A13: 0 | B13: =AVERAGE('Gradient condition'!C9,'Gradient condition'!C17,'Gradient condition'!C25,'Gradient condition'!C33,'Gradient condition'!C41,'Gradient condition'!C51,'Gradient condition'!C59,'Gradient condition'!C67,'Gradient condition'!C75,'Gradient condition'!C83,'Gradient condition'!C91,'Gradient condition'!C99,'Gradient condition'!C107,'Gradient condition'!C115) -> 18394.643 | C13: =B13*$B$1^2 -> 26967.157 | D13: =C13/C$13 -> 1 | E13: =STDEV('Gradient condition'!C9,'Gradient condition'!C17,'Gradient condition'!C25,'Gradient condition'!C33,'Gradient condition'!C41,'Gradient condition'!C51,'Gradient condition'!C59,'Gradient condition'!C67,'Gradient condition'!C75,'Gradient condition'!C83,'Gradient condition'!C91,'Gradient condition'!C99,'Gradient condition'!C107,'Gradient condition'!C115)/SQRT(COUNT('Gradient condition'!C9,'Gradient condition'!C17,'Gradient condition'!C25,'Gradient condition'!C33,'Gradient condition'!C41,'Gradient condition'!C51,'Gradient condition'!C59,'Gradient condition'!C67,'Gradient condition'!C75,'Gradient condition'!C83,'Gradient condition'!C91,'Gradient condition'!C99,'Gradient condition'!C107,'Gradient condition'!C115))*B$1*B$1 -> 4862.8408 | G13: 0 | H13: =AVERAGE('Gradient condition'!N9,'Gradient condition'!N17,'Gradient condition'!N25,'Gradient condition'!N33,'Gradient condition'!N41,'Gradient condition'!N51,'Gradient condition'!N59,'Gradient condition'!N67,'Gradient condition'!N75,'Gradient condition'!N83,'Gradient condition'!N91,'Gradient condition'!N99,'Gradient condition'!N107,'Gradient condition'!N115) -> 7749.5 | I13: =H13*$B$1^2 -> 11361.024 | J13: =I13/I$13 -> 1 | K13: =STDEV('Gradient condition'!N9,'Gradient condition'!N17,'Gradient condition'!N25,'Gradient condition'!N33,'Gradient condition'!N41,'Gradient condition'!N51,'Gradient condition'!N59,'Gradient condition'!N67,'Gradient condition'!N75,'Gradient condition'!N83,'Gradient condition'!N91,'Gradient condition'!N99,'Gradient condition'!N107,'Gradient condition'!N115)/SQRT(COUNT('Gradient condition'!N9,'Gradient condition'!N17,'Gradient condition'!N25,'Gradient condition'!N33,'Gradient condition'!N41,'Gradient condition'!N51,'Gradient condition'!N59,'Gradient condition'!N67,'Gradient condition'!N75,'Gradient condition'!N83,'Gradient condition'!N91,'Gradient condition'!N99,'Gradient condition'!N107,'Gradient condition'!N115))*B$1*B$1 -> 2614.4093
A14: 12 | B14: =AVERAGE('Gradient condition'!C10,'Gradient condition'!C18,'Gradient condition'!C26,'Gradient condition'!C34,'Gradient condition'!C42,'Gradient condition'!C52,'Gradient condition'!C60,'Gradient condition'!C68,'Gradient condition'!C76,'Gradient condition'!C84,'Gradient condition'!C92,'Gradient condition'!C100,'Gradient condition'!C108,'Gradient condition'!C116) -> 28894.857 | C14: =B14*$B$1^2 -> 42360.82 | D14: =C14/C$13 -> 1.57083 | E14: =STDEV('Gradient condition'!C10,'Gradient condition'!C18,'Gradient condition'!C26,'Gradient condition'!C34,'Gradient condition'!C42,'Gradient condition'!C52,'Gradient condition'!C60,'Gradient condition'!C68,'Gradient condition'!C76,'Gradient condition'!C84,'Gradient condition'!C92,'Gradient condition'!C100,'Gradient condition'!C108,'Gradient condition'!C116)/SQRT(COUNT('Gradient condition'!C10,'Gradient condition'!C18,'Gradient condition'!C26,'Gradient condition'!C34,'Gradient condition'!C42,'Gradient condition'!C52,'Gradient condition'!C60,'Gradient condition'!C68,'Gradient condition'!C76,'Gradient condition'!C84,'Gradient condition'!C92,'Gradient condition'!C100,'Gradient condition'!C108,'Gradient condition'!C116))*B$1*B$1 -> 9248.3276 | G14: 12 | H14: =AVERAGE('Gradient condition'!N10,'Gradient condition'!N18,'Gradient condition'!N26,'Gradient condition'!N34,'Gradient condition'!N42,'Gradient condition'!N52,'Gradient condition'!N60,'Gradient condition'!N68,'Gradient condition'!N76,'Gradient condition'!N84,'Gradient condition'!N92,'Gradient condition'!N100,'Gradient condition'!N108,'Gradient condition'!N116) -> 9734 | I14: =H14*$B$1^2 -> 14270.367 | J14: =I14/I$13 -> 1.256081 | K14: =STDEV('Gradient condition'!N10,'Gradient condition'!N18,'Gradient condition'!N26,'Gradient condition'!N34,'Gradient condition'!N42,'Gradient condition'!N52,'Gradient condition'!N60,'Gradient condition'!N68,'Gradient condition'!N76,'Gradient condition'!N84,'Gradient condition'!N92,'Gradient condition'!N100,'Gradient condition'!N108,'Gradient condition'!N116)/SQRT(COUNT('Gradient condition'!N10,'Gradient condition'!N18,'Gradient condition'!N26,'Gradient condition'!N34,'Gradient condition'!N42,'Gradient condition'!N52,'Gradient condition'!N60,'Gradient condition'!N68,'Gradient condition'!N76,'Gradient condition'!N84,'Gradient condition'!N92,'Gradient condition'!N100,'Gradient condition'!N108,'Gradient condition'!N116))*B$1*B$1 -> 3575.9562
A15: 24 | B15: =AVERAGE('Gradient condition'!C11,'Gradient condition'!C19,'Gradient condition'!C27,'Gradient condition'!C35,'Gradient condition'!C43,'Gradient condition'!C53,'Gradient condition'!C61,'Gradient condition'!C69,'Gradient condition'!C77,'Gradient condition'!C85,'Gradient condition'!C93,'Gradient condition'!C101,'Gradient condition'!C109,'Gradient condition'!C117) -> 37498 | C15: =B15*$B$1^2 -> 54973.313 | D15: =C15/C$13 -> 2.0385283 | E15: =STDEV('Gradient condition'!C11,'Gradient condition'!C19,'Gradient condition'!C27,'Gradient condition'!C35,'Gradient condition'!C43,'Gradient condition'!C53,'Gradient condition'!C61,'Gradient condition'!C69,'Gradient condition'!C77,'Gradient condition'!C85,'Gradient condition'!C93,'Gradient condition'!C101,'Gradient condition'!C109,'Gradient condition'!C117)/SQRT(COUNT('Gradient condition'!C11,'Gradient condition'!C19,'Gradient condition'!C27,'Gradient condition'!C35,'Gradient condition'!C43,'Gradient condition'!C53,'Gradient condition'!C61,'Gradient condition'!C69,'Gradient condition'!C77,'Gradient condition'!C85,'Gradient condition'!C93,'Gradient condition'!C101,'Gradient condition'!C109,'Gradient condition'!C117))*B$1*B$1 -> 12006.67 | G15: 24 | H15: =AVERAGE('Gradient condition'!N11,'Gradient condition'!N19,'Gradient condition'!N27,'Gradient condition'!N35,'Gradient condition'!N43,'Gradient condition'!N53,'Gradient condition'!N61,'Gradient condition'!N69,'Gradient condition'!N77,'Gradient condition'!N85,'Gradient condition'!N93,'Gradient condition'!N101,'Gradient condition'!N109,'Gradient condition'!N117) -> 13394.769 | I15: =H15*$B$1^2 -> 19637.176 | J15: =I15/I$13 -> 1.7284688 | K15: =STDEV('Gradient condition'!N11,'Gradient condition'!N19,'Gradient condition'!N27,'Gradient condition'!N35,'Gradient condition'!N43,'Gradient condition'!N53,'Gradient condition'!N61,'Gradient condition'!N69,'Gradient condition'!N77,'Gradient condition'!N85,'Gradient condition'!N93,'Gradient condition'!N101,'Gradient condition'!N109,'Gradient condition'!N117)/SQRT(COUNT('Gradient condition'!N11,'Gradient condition'!N19,'Gradient condition'!N27,'Gradient condition'!N35,'Gradient condition'!N43,'Gradient condition'!N53,'Gradient condition'!N61,'Gradient condition'!N69,'Gradient condition'!N77,'Gradient condition'!N85,'Gradient condition'!N93,'Gradient condition'!N101,'Gradient condition'!N109,'Gradient condition'!N117))*B$1*B$1 -> 4571.2322
A16: 36 | B16: =AVERAGE('Gradient condition'!C12,'Gradient condition'!C20,'Gradient condition'!C28,'Gradient condition'!C36,'Gradient condition'!C44,'Gradient condition'!C54,'Gradient condition'!C62,'Gradient condition'!C70,'Gradient condition'!C78,'Gradient condition'!C86,'Gradient condition'!C94,'Gradient condition'!C102,'Gradient condition'!C110,'Gradient condition'!C118) -> 40104.786 | C16: =B16*$B$1^2 -> 58794.947 | D16: =C16/C$13 -> 2.1802427 | E16: =STDEV('Gradient condition'!C12,'Gradient condition'!C20,'Gradient condition'!C28,'Gradient condition'!C36,'Gradient condition'!C44,'Gradient condition'!C54,'Gradient condition'!C62,'Gradient condition'!C70,'Gradient condition'!C78,'Gradient condition'!C86,'Gradient condition'!C94,'Gradient condition'!C102,'Gradient condition'!C110,'Gradient condition'!C118)/SQRT(COUNT('Gradient condition'!C12,'Gradient condition'!C20,'Gradient condition'!C28,'Gradient condition'!C36,'Gradient condition'!C44,'Gradient condition'!C54,'Gradient condition'!C62,'Gradient condition'!C70,'Gradient condition'!C78,'Gradient condition'!C86,'Gradient condition'!C94,'Gradient condition'!C102,'Gradient condition'!C110,'Gradient condition'!C118))*B$1*B$1 -> 11326.634 | G16: 36 | H16: =AVERAGE('Gradient condition'!N12,'Gradient condition'!N20,'Gradient condition'!N28,'Gradient condition'!N36,'Gradient condition'!N44,'Gradient condition'!N54,'Gradient condition'!N62,'Gradient condition'!N70,'Gradient condition'!N78,'Gradient condition'!N86,'Gradient condition'!N94,'Gradient condition'!N102,'Gradient condition'!N110,'Gradient condition'!N118) -> 14012.214 | I16: =H16*$B$1^2 -> 20542.371 | J16: =I16/I$13 -> 1.8081443 | K16: =STDEV('Gradient condition'!N12,'Gradient condition'!N20,'Gradient condition'!N28,'Gradient condition'!N36,'Gradient condition'!N44,'Gradient condition'!N54,'Gradient condition'!N62,'Gradient condition'!N70,'Gradient condition'!N78,'Gradient condition'!N86,'Gradient condition'!N94,'Gradient condition'!N102,'Gradient condition'!N110,'Gradient condition'!N118)/SQRT(COUNT('Gradient condition'!N12,'Gradient condition'!N20,'Gradient condition'!N28,'Gradient condition'!N36,'Gradient condition'!N44,'Gradient condition'!N54,'Gradient condition'!N62,'Gradient condition'!N70,'Gradient condition'!N78,'Gradient condition'!N86,'Gradient condition'!N94,'Gradient condition'!N102,'Gradient condition'!N110,'Gradient condition'!N118))*B$1*B$1 -> 4047.4518
A17: 48 | B17: =AVERAGE('Gradient condition'!C13,'Gradient condition'!C21,'Gradient condition'!C29,'Gradient condition'!C37,'Gradient condition'!C45,'Gradient condition'!C55,'Gradient condition'!C63,'Gradient condition'!C71,'Gradient condition'!C79,'Gradient condition'!C87,'Gradient condition'!C95,'Gradient condition'!C103,'Gradient condition'!C111,'Gradient condition'!C119) -> 41001.286 | C17: =B17*$B$1^2 -> 60109.246 | D17: =C17/C$13 -> 2.2289797 | E17: =STDEV('Gradient condition'!C13,'Gradient condition'!C21,'Gradient condition'!C29,'Gradient condition'!C37,'Gradient condition'!C45,'Gradient condition'!C55,'Gradient condition'!C63,'Gradient condition'!C71,'Gradient condition'!C79,'Gradient condition'!C87,'Gradient condition'!C95,'Gradient condition'!C103,'Gradient condition'!C111,'Gradient condition'!C119)/SQRT(COUNT('Gradient condition'!C13,'Gradient condition'!C21,'Gradient condition'!C29,'Gradient condition'!C37,'Gradient condition'!C45,'Gradient condition'!C55,'Gradient condition'!C63,'Gradient condition'!C71,'Gradient condition'!C79,'Gradient condition'!C87,'Gradient condition'!C95,'Gradient condition'!C103,'Gradient condition'!C111,'Gradient condition'!C119))*B$1*B$1 -> 11561.296 | G17: 48 | H17: =AVERAGE('Gradient condition'!N13,'Gradient condition'!N21,'Gradient condition'!N29,'Gradient condition'!N37,'Gradient condition'!N45,'Gradient condition'!N55,'Gradient condition'!N63,'Gradient condition'!N71,'Gradient condition'!N79,'Gradient condition'!N87,'Gradient condition'!N95,'Gradient condition'!N103,'Gradient condition'!N111,'Gradient condition'!N119) -> 13546.786 | I17: =H17*$B$1^2 -> 19860.038 | J17: =I17/I$13 -> 1.7480851 | K17: =STDEV('Gradient condition'!N13,'Gradient condition'!N21,'Gradient condition'!N29,'Gradient condition'!N37,'Gradient condition'!N45,'Gradient condition'!N55,'Gradient condition'!N63,'Gradient condition'!N71,'Gradient condition'!N79,'Gradient condition'!N87,'Gradient condition'!N95,'Gradient condition'!N103,'Gradient condition'!N111,'Gradient condition'!N119)/SQRT(COUNT('Gradient condition'!N13,'Gradient condition'!N21,'Gradient condition'!N29,'Gradient condition'!N37,'Gradient condition'!N45,'Gradient condition'!N55,'Gradient condition'!N63,'Gradient condition'!N71,'Gradient condition'!N79,'Gradient condition'!N87,'Gradient condition'!N95,'Gradient condition'!N103,'Gradient condition'!N111,'Gradient condition'!N119))*B$1*B$1 -> 3603.9254
